<?xml version="1.0"?>
<robot xmlns:xacro="http://www.ros.org/wiki/xacro" name="sumo">
  <xacro:macro name="wheel" params="prefix radius reflect front">
    <link name="${prefix}_wheel">
      <visual>
        <geometry>
          <cylinder length="0.04" radius="${radius}"/>
        </geometry>
        <material name="black">
            <color rgba="0 0 0 1"/> <!-- Set color to black -->
        </material>
      </visual>
      <collision>
        <geometry>
          <cylinder length="0.04" radius="${radius}"/>
        </geometry>
        <surface>
          <friction>
            <ode>
              <mu>200.0</mu>
              <mu2>100.0</mu2>
            </ode>
          </friction>
        </surface>
      </collision>
      <inertial>
        <mass value="50"/>
        <inertia ixx="0.06" ixy="0.0" ixz="0.0" iyy="0.06" iyz="0.0" izz="0.25"/>
      </inertial>
    </link>
    
    <joint name="base_to_${prefix}_wheel" type="continuous">
      <axis xyz="0 0 1"/>
      <parent link="base_link"/>
      <child link="${prefix}_wheel"/>
      <origin rpy="1.57075 0 0" xyz="${0.16*front} ${0.16*reflect} 0.0"/>
    </joint>
    
    <transmission name="${prefix}_wheel_transmission">
      <type>transmission_interface/SimpleTransmission</type>
      <actuator name="$${prefix}_motor">
        <mechanicalReduction>1</mechanicalReduction>
      </actuator>
      <joint name="base_to_${prefix}_wheel">
        <hardwareInterface>hardware_interface/VelocityJointInterface</hardwareInterface>
      </joint>
    </transmission>
  </xacro:macro>
</robot>

